Workbook

Sheet Invoice Data
A1: Parent Invoices
A7: Parent ID | B7: Previous Balance | C7: Pay Plan | D7: Calculated Fee | E7: Enroled | F7: Siblings? | G7: Sibling Discount | H7: Arrears Penalty | I7: Helper Hours | J7: Emp? | K7: Helper Discount | L7: Invoice Amount | M7: Paid Amount | N7: New Balance
A8: 30008 | B8: 0 | D8: 11757 | E8: 3 | F8: =IF(E8>=2,"Y", "") -> Y | G8: =IF(F8="y",D8*5%,0) -> 587.85 | H8: =IF(AND(B8>0,C8<>"Y"),B8*10%,0) -> 0 | I8: 16 | K8: =IF(OR(I8>=16,J8),250,0) -> 250 | L8: ='Invoice Data'!$B8+'Invoice Data'!$D8-'Invoice Data'!$G8-'Invoice Data'!$K8+'Invoice Data'!$H8 -> 10919.15 | M8: =VLOOKUP('Invoice Data'!$A8,BPay!$B$4:$D$10,3,0) -> 11757 | P8: Total Paid | Q8: =SUM('Invoice Data'!$M$8:$M$658) -> #N/A
A9: 30017 | B9: 0 | D9: 5193 | E9: 1 | F9: =IF(E9>=2,"Y", "") | G9: =IF(F9="y",D9*5%,0) -> 0 | H9: =IF(AND(B9>0,C9<>"Y"),B9*10%,0) -> 0 | I9: 0 | J9: TRUE | K9: =IF(OR(I9>=16,J9),250,0) -> 250 | L9: ='Invoice Data'!$B9+'Invoice Data'!$D9-'Invoice Data'!$G9-'Invoice Data'!$K9+'Invoice Data'!$H9 -> 4943 | M9: =VLOOKUP('Invoice Data'!$A9,BPay!$B$4:$D$10,3,0) -> 5193 | P9: Average New Balance | Q9: =AVERAGE('Invoice Data'!$N$8:$N$658) -> #DIV/0!
A10: 30035 | B10: 3645 | D10: 5086 | E10: 1 | F10: =IF(E10>=2,"Y", "") | G10: =IF(F10="y",D10*5%,0) -> 0 | H10: =IF(AND(B10>0,C10<>"Y"),B10*10%,0) -> 364.5 | I10: 5 | K10: =IF(OR(I10>=16,J10),250,0) -> 0 | L10: ='Invoice Data'!$B10+'Invoice Data'!$D10-'Invoice Data'!$G10-'Invoice Data'!$K10+'Invoice Data'!$H10 -> 9095.5 | M10: =VLOOKUP('Invoice Data'!$A10,BPay!$B$4:$D$10,3,0) -> 8731
A11: 30044 | B11: 548.45 | C11: Y | D11: 3589 | E11: 1 | F11: =IF(E11>=2,"Y", "") | G11: =IF(F11="y",D11*5%,0) -> 0 | H11: =IF(AND(B11>0,C11<>"Y"),B11*10%,0) -> 0 | I11: 6 | K11: =IF(OR(I11>=16,J11),250,0) -> 0 | L11: ='Invoice Data'!$B11+'Invoice Data'!$D11-'Invoice Data'!$G11-'Invoice Data'!$K11+'Invoice Data'!$H11 -> 4137.45 | M11: =VLOOKUP('Invoice Data'!$A11,BPay!$B$4:$D$10,3,0) -> 3589
A12: 30053 | B12: 0 | D12: 7377 | E12: 2 | F12: =IF(E12>=2,"Y", "") -> Y | G12: =IF(F12="y",D12*5%,0) -> 368.85 | H12: =IF(AND(B12>0,C12<>"Y"),B12*10%,0) -> 0 | I12: 0 | K12: =IF(OR(I12>=16,J12),250,0) -> 0 | L12: ='Invoice Data'!$B12+'Invoice Data'!$D12-'Invoice Data'!$G12-'Invoice Data'!$K12+'Invoice Data'!$H12 -> 7008.15 | M12: =VLOOKUP('Invoice Data'!$A12,BPay!$B$4:$D$10,3,0) -> 7377
A13: 30099 | B13: 0 | D13: 3554 | E13: 1 | F13: =IF(E13>=2,"Y", "") | G13: =IF(F13="y",D13*5%,0) -> 0 | H13: =IF(AND(B13>0,C13<>"Y"),B13*10%,0) -> 0 | I13: 9 | K13: =IF(OR(I13>=16,J13),250,0) -> 0 | L13: ='Invoice Data'!$B13+'Invoice Data'!$D13-'Invoice Data'!$G13-'Invoice Data'!$K13+'Invoice Data'!$H13 -> 3554 | M13: =VLOOKUP('Invoice Data'!$A13,BPay!$B$4:$D$10,3,0) -> #N/A
A14: 30115 | B14: -1200 | D14: 4650 | E14: 1 | F14: =IF(E14>=2,"Y", "") | G14: =IF(F14="y",D14*5%,0) -> 0 | H14: =IF(AND(B14>0,C14<>"Y"),B14*10%,0) -> 0 | I14: 0 | J14: TRUE | K14: =IF(OR(I14>=16,J14),250,0) -> 250 | L14: ='Invoice Data'!$B14+'Invoice Data'!$D14-'Invoice Data'!$G14-'Invoice Data'!$K14+'Invoice Data'!$H14 -> 3200 | M14: =VLOOKUP('Invoice Data'!$A14,BPay!$B$4:$D$10,3,0) -> #N/A
A15: 30133 | B15: 0 | D15: 9031 | E15: 2 | F15: =IF(E15>=2,"Y", "") -> Y | G15: =IF(F15="y",D15*5%,0) -> 451.55 | H15: =IF(AND(B15>0,C15<>"Y"),B15*10%,0) -> 0 | I15: 7 | K15: =IF(OR(I15>=16,J15),250,0) -> 0 | L15: ='Invoice Data'!$B15+'Invoice Data'!$D15-'Invoice Data'!$G15-'Invoice Data'!$K15+'Invoice Data'!$H15 -> 8579.45 | M15: =VLOOKUP('Invoice Data'!$A15,BPay!$B$4:$D$10,3,0) -> 7377
A16: 30142 | B16: 0 | D16: 3943 | E16: 1 | F16: =IF(E16>=2,"Y", "") | G16: =IF(F16="y",D16*5%,0) -> 0 | H16: =IF(AND(B16>0,C16<>"Y"),B16*10%,0) -> 0 | I16: 2 | K16: =IF(OR(I16>=16,J16),250,0) -> 0 | L16: ='Invoice Data'!$B16+'Invoice Data'!$D16-'Invoice Data'!$G16-'Invoice Data'!$K16+'Invoice Data'!$H16 -> 3943 | M16: =VLOOKUP('Invoice Data'!$A16,BPay!$B$4:$D$10,3,0) -> #N/A
A17: 30151 | B17: 0 | D17: 4197 | E17: 1 | F17: =IF(E17>=2,"Y", "") | G17: =IF(F17="y",D17*5%,0) -> 0 | H17: =IF(AND(B17>0,C17<>"Y"),B17*10%,0) -> 0 | I17: 16 | K17: =IF(OR(I17>=16,J17),250,0) -> 250 | L17: ='Invoice Data'!$B17+'Invoice Data'!$D17-'Invoice Data'!$G17-'Invoice Data'!$K17+'Invoice Data'!$H17 -> 3947 | M17: =VLOOKUP('Invoice Data'!$A17,BPay!$B$4:$D$10,3,0) -> #N/A
A18: 30160 | B18: 0 | D18: 8234 | E18: 2 | F18: =IF(E18>=2,"Y", "") -> Y | G18: =IF(F18="y",D18*5%,0) -> 411.7 | H18: =IF(AND(B18>0,C18<>"Y"),B18*10%,0) -> 0 | I18: 18 | K18: =IF(OR(I18>=16,J18),250,0) -> 250 | L18: ='Invoice Data'!$B18+'Invoice Data'!$D18-'Invoice Data'!$G18-'Invoice Data'!$K18+'Invoice Data'!$H18 -> 7572.3 | M18: =VLOOKUP('Invoice Data'!$A18,BPay!$B$4:$D$10,3,0) -> #N/A
A19: 30188 | B19: 0 | D19: 6278 | E19: 2 | F19: =IF(E19>=2,"Y", "") -> Y | G19: =IF(F19="y",D19*5%,0) -> 313.9 | H19: =IF(AND(B19>0,C19<>"Y"),B19*10%,0) -> 0 | I19: 16 | K19: =IF(OR(I19>=16,J19),250,0) -> 250 | L19: ='Invoice Data'!$B19+'Invoice Data'!$D19-'Invoice Data'!$G19-'Invoice Data'!$K19+'Invoice Data'!$H19 -> 5714.1 | M19: =VLOOKUP('Invoice Data'!$A19,BPay!$B$4:$D$10,3,0) -> #N/A
A20: 30197 | B20: 0 | D20: 18626 | E20: 4 | F20: =IF(E20>=2,"Y", "") -> Y | G20: =IF(F20="y",D20*5%,0) -> 931.3 | H20: =IF(AND(B20>0,C20<>"Y"),B20*10%,0) -> 0 | I20: 0 | K20: =IF(OR(I20>=16,J20),250,0) -> 0 | L20: ='Invoice Data'!$B20+'Invoice Data'!$D20-'Invoice Data'!$G20-'Invoice Data'!$K20+'Invoice Data'!$H20 -> 17694.7 | M20: =VLOOKUP('Invoice Data'!$A20,BPay!$B$4:$D$10,3,0) -> #N/A
A21: 30204 | B21: 0 | D21: 9386 | E21: 2 | F21: =IF(E21>=2,"Y", "") -> Y | G21: =IF(F21="y",D21*5%,0) -> 469.3 | H21: =IF(AND(B21>0,C21<>"Y"),B21*10%,0) -> 0 | I21: 0 | J21: TRUE | K21: =IF(OR(I21>=16,J21),250,0) -> 250 | L21: ='Invoice Data'!$B21+'Invoice Data'!$D21-'Invoice Data'!$G21-'Invoice Data'!$K21+'Invoice Data'!$H21 -> 8666.7 | M21: =VLOOKUP('Invoice Data'!$A21,BPay!$B$4:$D$10,3,0) -> #N/A
A22: 30213 | B22: 0 | D22: 10092 | E22: 2 | F22: =IF(E22>=2,"Y", "") -> Y | G22: =IF(F22="y",D22*5%,0) -> 504.6 | H22: =IF(AND(B22>0,C22<>"Y"),B22*10%,0) -> 0 | I22: 10 | K22: =IF(OR(I22>=16,J22),250,0) -> 0 | L22: ='Invoice Data'!$B22+'Invoice Data'!$D22-'Invoice Data'!$G22-'Invoice Data'!$K22+'Invoice Data'!$H22 -> 9587.4 | M22: =VLOOKUP('Invoice Data'!$A22,BPay!$B$4:$D$10,3,0) -> #N/A
A23: 30222 | B23: 0 | D23: 3838 | E23: 1 | F23: =IF(E23>=2,"Y", "") | G23: =IF(F23="y",D23*5%,0) -> 0 | H23: =IF(AND(B23>0,C23<>"Y"),B23*10%,0) -> 0 | I23: 3 | K23: =IF(OR(I23>=16,J23),250,0) -> 0 | L23: ='Invoice Data'!$B23+'Invoice Data'!$D23-'Invoice Data'!$G23-'Invoice Data'!$K23+'Invoice Data'!$H23 -> 3838 | M23: =VLOOKUP('Invoice Data'!$A23,BPay!$B$4:$D$10,3,0) -> 3838
A24: 30240 | B24: 0 | D24: 4160 | E24: 1 | F24: =IF(E24>=2,"Y", "") | G24: =IF(F24="y",D24*5%,0) -> 0 | H24: =IF(AND(B24>0,C24<>"Y"),B24*10%,0) -> 0 | I24: 2 | K24: =IF(OR(I24>=16,J24),250,0) -> 0 | L24: ='Invoice Data'!$B24+'Invoice Data'!$D24-'Invoice Data'!$G24-'Invoice Data'!$K24+'Invoice Data'!$H24 -> 4160 | M24: =VLOOKUP('Invoice Data'!$A24,BPay!$B$4:$D$10,3,0) -> #N/A
A25: 30259 | B25: 0 | D25: 7875 | E25: 2 | F25: =IF(E25>=2,"Y", "") -> Y | G25: =IF(F25="y",D25*5%,0) -> 393.75 | H25: =IF(AND(B25>0,C25<>"Y"),B25*10%,0) -> 0 | I25: 1 | K25: =IF(OR(I25>=16,J25),250,0) -> 0 | L25: ='Invoice Data'!$B25+'Invoice Data'!$D25-'Invoice Data'!$G25-'Invoice Data'!$K25+'Invoice Data'!$H25 -> 7481.25 | M25: =VLOOKUP('Invoice Data'!$A25,BPay!$B$4:$D$10,3,0) -> #N/A
A26: 30268 | B26: 2279 | D26: 8867 | E26: 2 | F26: =IF(E26>=2,"Y", "") -> Y | G26: =IF(F26="y",D26*5%,0) -> 443.35 | H26: =IF(AND(B26>0,C26<>"Y"),B26*10%,0) -> 227.9 | I26: 16 | K26: =IF(OR(I26>=16,J26),250,0) -> 250 | L26: ='Invoice Data'!$B26+'Invoice Data'!$D26-'Invoice Data'!$G26-'Invoice Data'!$K26+'Invoice Data'!$H26 -> 10680.55 | M26: =VLOOKUP('Invoice Data'!$A26,BPay!$B$4:$D$10,3,0) -> #N/A
A27: 30277 | B27: 0 | D27: 9970 | E27: 2 | F27: =IF(E27>=2,"Y", "") -> Y | G27: =IF(F27="y",D27*5%,0) -> 498.5 | H27: =IF(AND(B27>0,C27<>"Y"),B27*10%,0) -> 0 | I27: 0 | K27: =IF(OR(I27>=16,J27),250,0) -> 0 | L27: ='Invoice Data'!$B27+'Invoice Data'!$D27-'Invoice Data'!$G27-'Invoice Data'!$K27+'Invoice Data'!$H27 -> 9471.5 | M27: =VLOOKUP('Invoice Data'!$A27,BPay!$B$4:$D$10,3,0) -> #N/A
A28: 30295 | B28: 0 | D28: 9383 | E28: 2 | F28: =IF(E28>=2,"Y", "") -> Y | G28: =IF(F28="y",D28*5%,0) -> 469.15 | H28: =IF(AND(B28>0,C28<>"Y"),B28*10%,0) -> 0 | I28: 16 | K28: =IF(OR(I28>=16,J28),250,0) -> 250 | L28: ='Invoice Data'!$B28+'Invoice Data'!$D28-'Invoice Data'!$G28-'Invoice Data'!$K28+'Invoice Data'!$H28 -> 8663.85 | M28: =VLOOKUP('Invoice Data'!$A28,BPay!$B$4:$D$10,3,0) -> #N/A
A29: 30357 | B29: -200 | D29: 5449 | E29: 1 | F29: =IF(E29>=2,"Y", "") | G29: =IF(F29="y",D29*5%,0) -> 0 | H29: =IF(AND(B29>0,C29<>"Y"),B29*10%,0) -> 0 | I29: 16 | K29: =IF(OR(I29>=16,J29),250,0) -> 250 | L29: ='Invoice Data'!$B29+'Invoice Data'!$D29-'Invoice Data'!$G29-'Invoice Data'!$K29+'Invoice Data'!$H29 -> 4999 | M29: =VLOOKUP('Invoice Data'!$A29,BPay!$B$4:$D$10,3,0) -> #N/A
A30: 30366 | B30: 0 | D30: 6429 | E30: 2 | F30: =IF(E30>=2,"Y", "") -> Y | G30: =IF(F30="y",D30*5%,0) -> 321.45 | H30: =IF(AND(B30>0,C30<>"Y"),B30*10%,0) -> 0 | I30: 10 | K30: =IF(OR(I30>=16,J30),250,0) -> 0 | L30: ='Invoice Data'!$B30+'Invoice Data'!$D30-'Invoice Data'!$G30-'Invoice Data'!$K30+'Invoice Data'!$H30 -> 6107.55 | M30: =VLOOKUP('Invoice Data'!$A30,BPay!$B$4:$D$10,3,0) -> #N/A
A31: 30400 | B31: 0 | D31: 9103 | E31: 2 | F31: =IF(E31>=2,"Y", "") -> Y | G31: =IF(F31="y",D31*5%,0) -> 455.15 | H31: =IF(AND(B31>0,C31<>"Y"),B31*10%,0) -> 0 | I31: 13 | K31: =IF(OR(I31>=16,J31),250,0) -> 0 | L31: ='Invoice Data'!$B31+'Invoice Data'!$D31-'Invoice Data'!$G31-'Invoice Data'!$K31+'Invoice Data'!$H31 -> 8647.85 | M31: =VLOOKUP('Invoice Data'!$A31,BPay!$B$4:$D$10,3,0) -> #N/A
A32: 30428 | B32: 0 | D32: 3812 | E32: 1 | F32: =IF(E32>=2,"Y", "") | G32: =IF(F32="y",D32*5%,0) -> 0 | H32: =IF(AND(B32>0,C32<>"Y"),B32*10%,0) -> 0 | I32: 6 | K32: =IF(OR(I32>=16,J32),250,0) -> 0 | L32: ='Invoice Data'!$B32+'Invoice Data'!$D32-'Invoice Data'!$G32-'Invoice Data'!$K32+'Invoice Data'!$H32 -> 3812 | M32: =VLOOKUP('Invoice Data'!$A32,BPay!$B$4:$D$10,3,0) -> #N/A
A33: 30437 | B33: 0 | D33: 4749 | E33: 1 | F33: =IF(E33>=2,"Y", "") | G33: =IF(F33="y",D33*5%,0) -> 0 | H33: =IF(AND(B33>0,C33<>"Y"),B33*10%,0) -> 0 | I33: 2 | K33: =IF(OR(I33>=16,J33),250,0) -> 0 | L33: ='Invoice Data'!$B33+'Invoice Data'!$D33-'Invoice Data'!$G33-'Invoice Data'!$K33+'Invoice Data'!$H33 -> 4749 | M33: =VLOOKUP('Invoice Data'!$A33,BPay!$B$4:$D$10,3,0) -> #N/A
... A36: 30464 | B36: 0 | D36: 4597 | E36: 1 | F36: =IF(E36>=2,"Y", "") | G36: =IF(F36="y",D36*5%,0) -> 0 | H36: =IF(AND(B36>0,C36<>"Y"),B36*10%,0) -> 0 | I36: 2 | K36: =IF(OR(I36>=16,J36),250,0) -> 0 | L36: ='Invoice Data'!$B36+'Invoice Data'!$D36-'Invoice Data'!$G36-'Invoice Data'!$K36+'Invoice Data'!$H36 -> 4597 | M36: =VLOOKUP('Invoice Data'!$A36,BPay!$B$4:$D$10,3,0) -> #N/A
A37: 30473 | B37: 0 | D37: 4239 | E37: 1 | F37: =IF(E37>=2,"Y", "") | G37: =IF(F37="y",D37*5%,0) -> 0 | H37: =IF(AND(B37>0,C37<>"Y"),B37*10%,0) -> 0 | I37: 0 | J37: TRUE | K37: =IF(OR(I37>=16,J37),250,0) -> 250 | L37: ='Invoice Data'!$B37+'Invoice Data'!$D37-'Invoice Data'!$G37-'Invoice Data'!$K37+'Invoice Data'!$H37 -> 3989 | M37: =VLOOKUP('Invoice Data'!$A37,BPay!$B$4:$D$10,3,0) -> #N/A
A38: 30482 | B38: 0 | D38: 3736 | E38: 1 | F38: =IF(E38>=2,"Y", "") | G38: =IF(F38="y",D38*5%,0) -> 0 | H38: =IF(AND(B38>0,C38<>"Y"),B38*10%,0) -> 0 | I38: 0 | K38: =IF(OR(I38>=16,J38),250,0) -> 0 | L38: ='Invoice Data'!$B38+'Invoice Data'!$D38-'Invoice Data'!$G38-'Invoice Data'!$K38+'Invoice Data'!$H38 -> 3736 | M38: =VLOOKUP('Invoice Data'!$A38,BPay!$B$4:$D$10,3,0) -> #N/A
A39: 30491 | B39: 0 | D39: 5111 | E39: 1 | F39: =IF(E39>=2,"Y", "") | G39: =IF(F39="y",D39*5%,0) -> 0 | H39: =IF(AND(B39>0,C39<>"Y"),B39*10%,0) -> 0 | I39: 6 | K39: =IF(OR(I39>=16,J39),250,0) -> 0 | L39: ='Invoice Data'!$B39+'Invoice Data'!$D39-'Invoice Data'!$G39-'Invoice Data'!$K39+'Invoice Data'!$H39 -> 5111 | M39: =VLOOKUP('Invoice Data'!$A39,BPay!$B$4:$D$10,3,0) -> #N/A
A40: 30623 | B40: 0 | D40: 8470 | E40: 2 | F40: =IF(E40>=2,"Y", "") -> Y | G40: =IF(F40="y",D40*5%,0) -> 423.5 | H40: =IF(AND(B40>0,C40<>"Y"),B40*10%,0) -> 0 | I40: 13 | K40: =IF(OR(I40>=16,J40),250,0) -> 0 | L40: ='Invoice Data'!$B40+'Invoice Data'!$D40-'Invoice Data'!$G40-'Invoice Data'!$K40+'Invoice Data'!$H40 -> 8046.5 | M40: =VLOOKUP('Invoice Data'!$A40,BPay!$B$4:$D$10,3,0) -> #N/A
A41: 30632 | B41: 0 | D41: 4365 | E41: 1 | F41: =IF(E41>=2,"Y", "") | G41: =IF(F41="y",D41*5%,0) -> 0 | H41: =IF(AND(B41>0,C41<>"Y"),B41*10%,0) -> 0 | I41: 0 | K41: =IF(OR(I41>=16,J41),250,0) -> 0 | L41: ='Invoice Data'!$B41+'Invoice Data'!$D41-'Invoice Data'!$G41-'Invoice Data'!$K41+'Invoice Data'!$H41 -> 4365 | M41: =VLOOKUP('Invoice Data'!$A41,BPay!$B$4:$D$10,3,0) -> #N/A
A42: 30650 | B42: 0 | D42: 9405 | E42: 2 | F42: =IF(E42>=2,"Y", "") -> Y | G42: =IF(F42="y",D42*5%,0) -> 470.25 | H42: =IF(AND(B42>0,C42<>"Y"),B42*10%,0) -> 0 | I42: 3 | K42: =IF(OR(I42>=16,J42),250,0) -> 0 | L42: ='Invoice Data'!$B42+'Invoice Data'!$D42-'Invoice Data'!$G42-'Invoice Data'!$K42+'Invoice Data'!$H42 -> 8934.75 | M42: =VLOOKUP('Invoice Data'!$A42,BPay!$B$4:$D$10,3,0) -> #N/A
A43: 30678 | B43: 0 | D43: 3549 | E43: 1 | F43: =IF(E43>=2,"Y", "") | G43: =IF(F43="y",D43*5%,0) -> 0 | H43: =IF(AND(B43>0,C43<>"Y"),B43*10%,0) -> 0 | I43: 15 | K43: =IF(OR(I43>=16,J43),250,0) -> 0 | L43: ='Invoice Data'!$B43+'Invoice Data'!$D43-'Invoice Data'!$G43-'Invoice Data'!$K43+'Invoice Data'!$H43 -> 3549 | M43: =VLOOKUP('Invoice Data'!$A43,BPay!$B$4:$D$10,3,0) -> #N/A
A44: 30696 | B44: 0 | D44: 5218 | E44: 1 | F44: =IF(E44>=2,"Y", "") | G44: =IF(F44="y",D44*5%,0) -> 0 | H44: =IF(AND(B44>0,C44<>"Y"),B44*10%,0) -> 0 | I44: 12 | K44: =IF(OR(I44>=16,J44),250,0) -> 0 | L44: ='Invoice Data'!$B44+'Invoice Data'!$D44-'Invoice Data'!$G44-'Invoice Data'!$K44+'Invoice Data'!$H44 -> 5218 | M44: =VLOOKUP('Invoice Data'!$A44,BPay!$B$4:$D$10,3,0) -> #N/A
A45: 30721 | B45: 0 | D45: 9778 | E45: 2 | F45: =IF(E45>=2,"Y", "") -> Y | G45: =IF(F45="y",D45*5%,0) -> 488.9 | H45: =IF(AND(B45>0,C45<>"Y"),B45*10%,0) -> 0 | I45: 1 | K45: =IF(OR(I45>=16,J45),250,0) -> 0 | L45: ='Invoice Data'!$B45+'Invoice Data'!$D45-'Invoice Data'!$G45-'Invoice Data'!$K45+'Invoice Data'!$H45 -> 9289.1 | M45: =VLOOKUP('Invoice Data'!$A45,BPay!$B$4:$D$10,3,0) -> #N/A
A46: 30730 | B46: 0 | D46: 3347 | E46: 1 | F46: =IF(E46>=2,"Y", "") | G46: =IF(F46="y",D46*5%,0) -> 0 | H46: =IF(AND(B46>0,C46<>"Y"),B46*10%,0) -> 0 | I46: 12 | K46: =IF(OR(I46>=16,J46),250,0) -> 0 | L46: ='Invoice Data'!$B46+'Invoice Data'!$D46-'Invoice Data'!$G46-'Invoice Data'!$K46+'Invoice Data'!$H46 -> 3347 | M46: =VLOOKUP('Invoice Data'!$A46,BPay!$B$4:$D$10,3,0) -> #N/A
A47: 30749 | B47: 0 | D47: 8605 | E47: 2 | F47: =IF(E47>=2,"Y", "") -> Y | G47: =IF(F47="y",D47*5%,0) -> 430.25 | H47: =IF(AND(B47>0,C47<>"Y"),B47*10%,0) -> 0 | I47: 4 | K47: =IF(OR(I47>=16,J47),250,0) -> 0 | L47: ='Invoice Data'!$B47+'Invoice Data'!$D47-'Invoice Data'!$G47-'Invoice Data'!$K47+'Invoice Data'!$H47 -> 8174.75 | M47: =VLOOKUP('Invoice Data'!$A47,BPay!$B$4:$D$10,3,0) -> #N/A
...

Sheet BPay
A1: Bpay Upload
A3: Merchant ID | B3: Bpay Reference | C3: Paid Date | D3: Transaction Amount
A4: 190483155 | B4: 30008 | C4: 42957 | D4: 11757
A5: 190483155 | B5: 30017 | C5: 42957 | D5: 5193
A6: 190483155 | B6: 30035 | C6: 42957 | D6: 8731
A7: 190483155 | B7: 30044 | C7: 42957 | D7: =3041+548 -> 3589
A8: 190483155 | B8: 30133 | C8: 42959 | D8: 7377
A9: 190483155 | B9: 30053 | C9: 42959 | D9: 7377
A10: 190483155 | B10: 30222 | C10: 42960 | D10: 3838
